Workbook

Sheet Inputs
A1: SPIA Inputs
A3: Issue Age | B3: 65 | D3: Notes
A4: Sex | B4: male | D4: All rates are decimals.
A5: Annual Benefit | B5: 100000 | D5: Valuation date interpreted as 12/31/Valuation Year.
A6: Payment Frequency | B6: 12 | D6: Monthly expenses assumed paid while in-force.
A7: Valuation Year | B7: 2025
A8: Horizon Age | B8: 110
A9: Spread | B9: 0
A10: Policy Expense Dollars | B10: 250
A11: Premium Expense Rate | B11: 0.01
A12: Monthly Expense Dollars | B12: 25
A15: Derived
A16: Monthly Benefit | B16: =B5/B6 -> 8333.3333
A17: Projection Months | B17: =(B8-B3)*B6 -> 540

Sheet YieldCurve
A1: Treasury Zero Curve
A3: maturity_years | B3: zero_rate
A4: 0.5 | B4: 0.03725093
A5: 1 | B5: 0.0369537
A6: 1.5 | B6: 0.03725465
A7: 2 | B7: 0.03755667
A8: 2.5 | B8: 0.03755441
A9: 3 | B9: 0.0375529
A10: 3.5 | B10: 0.03778571
A11: 4 | B11: 0.03801957
A12: 4.5 | B12: 0.03825472
A13: 5 | B13: 0.03849135
A14: 5.5 | B14: 0.03897383
A15: 6 | B15: 0.03945938
... A63: 30 | B63: 0.04945471

Sheet RP2014_Qx
A1: RP-2014 Male Healthy Annuitant Base Qx (2014)
A3: age | B3: qx
A4: 50 | B4: 0.002768
A5: 51 | B5: 0.002905
A6: 52 | B6: 0.003057
A7: 53 | B7: 0.003225
A8: 54 | B8: 0.003412
A9: 55 | B9: 0.003622
A10: 56 | B10: 0.003858
A11: 57 | B11: 0.004128
A12: 58 | B12: 0.004436
A13: 59 | B13: 0.004789
A14: 60 | B14: 0.005191
A15: 61 | B15: 0.005646
... A74: 120 | B74: 1

Sheet MP2016_Long
A1: MP-2016 Male Improvement Rates (Long)
A3: age | B3: year | C3: improvement_rate
A4: 21 | B4: 1951 | C4: -0.0146
A5: 21 | B5: 1952 | C5: -0.0062
A6: 21 | B6: 1953 | C6: 0.002
A7: 21 | B7: 1954 | C7: 0.0092
A8: 21 | B8: 1955 | C8: 0.0151
A9: 21 | B9: 1956 | C9: 0.0193
A10: 21 | B10: 1957 | C10: 0.0215
A11: 21 | B11: 1958 | C11: 0.0211
A12: 21 | B12: 1959 | C12: 0.018
A13: 21 | B13: 1960 | C13: 0.0121
A14: 21 | B14: 1961 | C14: 0.0038
A15: 21 | B15: 1962 | C15: -0.0059
... A8103: 120 | B8103: 2031 | C8103: 0

Sheet MonthlyCurve
A1: Monthly Interpolated Zero Curve
A3: Month | B3: t_years | C3: BracketIndex | D3: LowerMat | E3: UpperMat | F3: LowerZero | G3: UpperZero | H3: InterpWeight | I3: ZeroRateInterpolated | J3: DiscountFactor
A4: 1 | B4: =A4/Inputs!$B$6 -> 0.083333333 | C4: =IF(B4<=INDEX(YieldCurve!$A$4:$A$63,1),1,IF(B4>=INDEX(YieldCurve!$A$4:$A$63,ROWS(YieldCurve!$A$4:$A$63)),ROWS(YieldCurve!$A$4:$A$63)-1,MATCH(B4,YieldCurve!$A$4:$A$63,1))) -> 1 | D4: =INDEX(YieldCurve!$A$4:$A$63,C4) -> 0.5 | E4: =INDEX(YieldCurve!$A$4:$A$63,C4+1) -> 1 | F4: =INDEX(YieldCurve!$B$4:$B$63,C4) -> 0.03725093 | G4: =INDEX(YieldCurve!$B$4:$B$63,C4+1) -> 0.0369537 | H4: =IF(E4=D4,0,(B4-D4)/(E4-D4)) -> -0.83333333 | I4: =IF(B4<=INDEX(YieldCurve!$A$4:$A$63,1),INDEX(YieldCurve!$B$4:$B$63,1),IF(B4>=INDEX(YieldCurve!$A$4:$A$63,ROWS(YieldCurve!$A$4:$A$63)),INDEX(YieldCurve!$B$4:$B$63,ROWS(YieldCurve!$B$4:$B$63)),F4+H4*(G4-F4))) -> 0.03725093 | J4: =EXP(-(I4+Inputs!$B$9)*B4) -> 0.99690057
A5: 2 | B5: =A5/Inputs!$B$6 -> 0.16666667 | C5: =IF(B5<=INDEX(YieldCurve!$A$4:$A$63,1),1,IF(B5>=INDEX(YieldCurve!$A$4:$A$63,ROWS(YieldCurve!$A$4:$A$63)),ROWS(YieldCurve!$A$4:$A$63)-1,MATCH(B5,YieldCurve!$A$4:$A$63,1))) -> 1 | D5: =INDEX(YieldCurve!$A$4:$A$63,C5) -> 0.5 | E5: =INDEX(YieldCurve!$A$4:$A$63,C5+1) -> 1 | F5: =INDEX(YieldCurve!$B$4:$B$63,C5) -> 0.03725093 | G5: =INDEX(YieldCurve!$B$4:$B$63,C5+1) -> 0.0369537 | H5: =IF(E5=D5,0,(B5-D5)/(E5-D5)) -> -0.66666667 | I5: =IF(B5<=INDEX(YieldCurve!$A$4:$A$63,1),INDEX(YieldCurve!$B$4:$B$63,1),IF(B5>=INDEX(YieldCurve!$A$4:$A$63,ROWS(YieldCurve!$A$4:$A$63)),INDEX(YieldCurve!$B$4:$B$63,ROWS(YieldCurve!$B$4:$B$63)),F5+H5*(G5-F5))) -> 0.03725093 | J5: =EXP(-(I5+Inputs!$B$9)*B5) -> 0.99381074
A6: 3 | B6: =A6/Inputs!$B$6 -> 0.25 | C6: =IF(B6<=INDEX(YieldCurve!$A$4:$A$63,1),1,IF(B6>=INDEX(YieldCurve!$A$4:$A$63,ROWS(YieldCurve!$A$4:$A$63)),ROWS(YieldCurve!$A$4:$A$63)-1,MATCH(B6,YieldCurve!$A$4:$A$63,1))) -> 1 | D6: =INDEX(YieldCurve!$A$4:$A$63,C6) -> 0.5 | E6: =INDEX(YieldCurve!$A$4:$A$63,C6+1) -> 1 | F6: =INDEX(YieldCurve!$B$4:$B$63,C6) -> 0.03725093 | G6: =INDEX(YieldCurve!$B$4:$B$63,C6+1) -> 0.0369537 | H6: =IF(E6=D6,0,(B6-D6)/(E6-D6)) -> -0.5 | I6: =IF(B6<=INDEX(YieldCurve!$A$4:$A$63,1),INDEX(YieldCurve!$B$4:$B$63,1),IF(B6>=INDEX(YieldCurve!$A$4:$A$63,ROWS(YieldCurve!$A$4:$A$63)),INDEX(YieldCurve!$B$4:$B$63,ROWS(YieldCurve!$B$4:$B$63)),F6+H6*(G6-F6))) -> 0.03725093 | J6: =EXP(-(I6+Inputs!$B$9)*B6) -> 0.9907305
A7: 4 | B7: =A7/Inputs!$B$6 -> 0.33333333 | C7: =IF(B7<=INDEX(YieldCurve!$A$4:$A$63,1),1,IF(B7>=INDEX(YieldCurve!$A$4:$A$63,ROWS(YieldCurve!$A$4:$A$63)),ROWS(YieldCurve!$A$4:$A$63)-1,MATCH(B7,YieldCurve!$A$4:$A$63,1))) -> 1 | D7: =INDEX(YieldCurve!$A$4:$A$63,C7) -> 0.5 | E7: =INDEX(YieldCurve!$A$4:$A$63,C7+1) -> 1 | F7: =INDEX(YieldCurve!$B$4:$B$63,C7) -> 0.03725093 | G7: =INDEX(YieldCurve!$B$4:$B$63,C7+1) -> 0.0369537 | H7: =IF(E7=D7,0,(B7-D7)/(E7-D7)) -> -0.33333333 | I7: =IF(B7<=INDEX(YieldCurve!$A$4:$A$63,1),INDEX(YieldCurve!$B$4:$B$63,1),IF(B7>=INDEX(YieldCurve!$A$4:$A$63,ROWS(YieldCurve!$A$4:$A$63)),INDEX(YieldCurve!$B$4:$B$63,ROWS(YieldCurve!$B$4:$B$63)),F7+H7*(G7-F7))) -> 0.03725093 | J7: =EXP(-(I7+Inputs!$B$9)*B7) -> 0.9876598
A8: 5 | B8: =A8/Inputs!$B$6 -> 0.41666667 | C8: =IF(B8<=INDEX(YieldCurve!$A$4:$A$63,1),1,IF(B8>=INDEX(YieldCurve!$A$4:$A$63,ROWS(YieldCurve!$A$4:$A$63)),ROWS(YieldCurve!$A$4:$A$63)-1,MATCH(B8,YieldCurve!$A$4:$A$63,1))) -> 1 | D8: =INDEX(YieldCurve!$A$4:$A$63,C8) -> 0.5 | E8: =INDEX(YieldCurve!$A$4:$A$63,C8+1) -> 1 | F8: =INDEX(YieldCurve!$B$4:$B$63,C8) -> 0.03725093 | G8: =INDEX(YieldCurve!$B$4:$B$63,C8+1) -> 0.0369537 | H8: =IF(E8=D8,0,(B8-D8)/(E8-D8)) -> -0.16666667 | I8: =IF(B8<=INDEX(YieldCurve!$A$4:$A$63,1),INDEX(YieldCurve!$B$4:$B$63,1),IF(B8>=INDEX(YieldCurve!$A$4:$A$63,ROWS(YieldCurve!$A$4:$A$63)),INDEX(YieldCurve!$B$4:$B$63,ROWS(YieldCurve!$B$4:$B$63)),F8+H8*(G8-F8))) -> 0.03725093 | J8: =EXP(-(I8+Inputs!$B$9)*B8) -> 0.98459861
A9: 6 | B9: =A9/Inputs!$B$6 -> 0.5 | C9: =IF(B9<=INDEX(YieldCurve!$A$4:$A$63,1),1,IF(B9>=INDEX(YieldCurve!$A$4:$A$63,ROWS(YieldCurve!$A$4:$A$63)),ROWS(YieldCurve!$A$4:$A$63)-1,MATCH(B9,YieldCurve!$A$4:$A$63,1))) -> 1 | D9: =INDEX(YieldCurve!$A$4:$A$63,C9) -> 0.5 | E9: =INDEX(YieldCurve!$A$4:$A$63,C9+1) -> 1 | F9: =INDEX(YieldCurve!$B$4:$B$63,C9) -> 0.03725093 | G9: =INDEX(YieldCurve!$B$4:$B$63,C9+1) -> 0.0369537 | H9: =IF(E9=D9,0,(B9-D9)/(E9-D9)) -> 0 | I9: =IF(B9<=INDEX(YieldCurve!$A$4:$A$63,1),INDEX(YieldCurve!$B$4:$B$63,1),IF(B9>=INDEX(YieldCurve!$A$4:$A$63,ROWS(YieldCurve!$A$4:$A$63)),INDEX(YieldCurve!$B$4:$B$63,ROWS(YieldCurve!$B$4:$B$63)),F9+H9*(G9-F9))) -> 0.03725093 | J9: =EXP(-(I9+Inputs!$B$9)*B9) -> 0.98154692
A10: 7 | B10: =A10/Inputs!$B$6 -> 0.58333333 | C10: =IF(B10<=INDEX(YieldCurve!$A$4:$A$63,1),1,IF(B10>=INDEX(YieldCurve!$A$4:$A$63,ROWS(YieldCurve!$A$4:$A$63)),ROWS(YieldCurve!$A$4:$A$63)-1,MATCH(B10,YieldCurve!$A$4:$A$63,1))) -> 1 | D10: =INDEX(YieldCurve!$A$4:$A$63,C10) -> 0.5 | E10: =INDEX(YieldCurve!$A$4:$A$63,C10+1) -> 1 | F10: =INDEX(YieldCurve!$B$4:$B$63,C10) -> 0.03725093 | G10: =INDEX(YieldCurve!$B$4:$B$63,C10+1) -> 0.0369537 | H10: =IF(E10=D10,0,(B10-D10)/(E10-D10)) -> 0.16666667 | I10: =IF(B10<=INDEX(YieldCurve!$A$4:$A$63,1),INDEX(YieldCurve!$B$4:$B$63,1),IF(B10>=INDEX(YieldCurve!$A$4:$A$63,ROWS(YieldCurve!$A$4:$A$63)),INDEX(YieldCurve!$B$4:$B$63,ROWS(YieldCurve!$B$4:$B$63)),F10+H10*(G10-F10))) -> 0.037201392 | J10: =EXP(-(I10+Inputs!$B$9)*B10) -> 0.97853296
A11: 8 | B11: =A11/Inputs!$B$6 -> 0.66666667 | C11: =IF(B11<=INDEX(YieldCurve!$A$4:$A$63,1),1,IF(B11>=INDEX(YieldCurve!$A$4:$A$63,ROWS(YieldCurve!$A$4:$A$63)),ROWS(YieldCurve!$A$4:$A$63)-1,MATCH(B11,YieldCurve!$A$4:$A$63,1))) -> 1 | D11: =INDEX(YieldCurve!$A$4:$A$63,C11) -> 0.5 | E11: =INDEX(YieldCurve!$A$4:$A$63,C11+1) -> 1 | F11: =INDEX(YieldCurve!$B$4:$B$63,C11) -> 0.03725093 | G11: =INDEX(YieldCurve!$B$4:$B$63,C11+1) -> 0.0369537 | H11: =IF(E11=D11,0,(B11-D11)/(E11-D11)) -> 0.33333333 | I11: =IF(B11<=INDEX(YieldCurve!$A$4:$A$63,1),INDEX(YieldCurve!$B$4:$B$63,1),IF(B11>=INDEX(YieldCurve!$A$4:$A$63,ROWS(YieldCurve!$A$4:$A$63)),INDEX(YieldCurve!$B$4:$B$63,ROWS(YieldCurve!$B$4:$B$63)),F11+H11*(G11-F11))) -> 0.037151853 | J11: =EXP(-(I11+Inputs!$B$9)*B11) -> 0.97553631
A12: 9 | B12: =A12/Inputs!$B$6 -> 0.75 | C12: =IF(B12<=INDEX(YieldCurve!$A$4:$A$63,1),1,IF(B12>=INDEX(YieldCurve!$A$4:$A$63,ROWS(YieldCurve!$A$4:$A$63)),ROWS(YieldCurve!$A$4:$A$63)-1,MATCH(B12,YieldCurve!$A$4:$A$63,1))) -> 1 | D12: =INDEX(YieldCurve!$A$4:$A$63,C12) -> 0.5 | E12: =INDEX(YieldCurve!$A$4:$A$63,C12+1) -> 1 | F12: =INDEX(YieldCurve!$B$4:$B$63,C12) -> 0.03725093 | G12: =INDEX(YieldCurve!$B$4:$B$63,C12+1) -> 0.0369537 | H12: =IF(E12=D12,0,(B12-D12)/(E12-D12)) -> 0.5 | I12: =IF(B12<=INDEX(YieldCurve!$A$4:$A$63,1),INDEX(YieldCurve!$B$4:$B$63,1),IF(B12>=INDEX(YieldCurve!$A$4:$A$63,ROWS(YieldCurve!$A$4:$A$63)),INDEX(YieldCurve!$B$4:$B$63,ROWS(YieldCurve!$B$4:$B$63)),F12+H12*(G12-F12))) -> 0.037102315 | J12: =EXP(-(I12+Inputs!$B$9)*B12) -> 0.97255686
A13: 10 | B13: =A13/Inputs!$B$6 -> 0.83333333 | C13: =IF(B13<=INDEX(YieldCurve!$A$4:$A$63,1),1,IF(B13>=INDEX(YieldCurve!$A$4:$A$63,ROWS(YieldCurve!$A$4:$A$63)),ROWS(YieldCurve!$A$4:$A$63)-1,MATCH(B13,YieldCurve!$A$4:$A$63,1))) -> 1 | D13: =INDEX(YieldCurve!$A$4:$A$63,C13) -> 0.5 | E13: =INDEX(YieldCurve!$A$4:$A$63,C13+1) -> 1 | F13: =INDEX(YieldCurve!$B$4:$B$63,C13) -> 0.03725093 | G13: =INDEX(YieldCurve!$B$4:$B$63,C13+1) -> 0.0369537 | H13: =IF(E13=D13,0,(B13-D13)/(E13-D13)) -> 0.66666667 | I13: =IF(B13<=INDEX(YieldCurve!$A$4:$A$63,1),INDEX(YieldCurve!$B$4:$B$63,1),IF(B13>=INDEX(YieldCurve!$A$4:$A$63,ROWS(YieldCurve!$A$4:$A$63)),INDEX(YieldCurve!$B$4:$B$63,ROWS(YieldCurve!$B$4:$B$63)),F13+H13*(G13-F13))) -> 0.037052777 | J13: =EXP(-(I13+Inputs!$B$9)*B13) -> 0.96959452
A14: 11 | B14: =A14/Inputs!$B$6 -> 0.91666667 | C14: =IF(B14<=INDEX(YieldCurve!$A$4:$A$63,1),1,IF(B14>=INDEX(YieldCurve!$A$4:$A$63,ROWS(YieldCurve!$A$4:$A$63)),ROWS(YieldCurve!$A$4:$A$63)-1,MATCH(B14,YieldCurve!$A$4:$A$63,1))) -> 1 | D14: =INDEX(YieldCurve!$A$4:$A$63,C14) -> 0.5 | E14: =INDEX(YieldCurve!$A$4:$A$63,C14+1) -> 1 | F14: =INDEX(YieldCurve!$B$4:$B$63,C14) -> 0.03725093 | G14: =INDEX(YieldCurve!$B$4:$B$63,C14+1) -> 0.0369537 | H14: =IF(E14=D14,0,(B14-D14)/(E14-D14)) -> 0.83333333 | I14: =IF(B14<=INDEX(YieldCurve!$A$4:$A$63,1),INDEX(YieldCurve!$B$4:$B$63,1),IF(B14>=INDEX(YieldCurve!$A$4:$A$63,ROWS(YieldCurve!$A$4:$A$63)),INDEX(YieldCurve!$B$4:$B$63,ROWS(YieldCurve!$B$4:$B$63)),F14+H14*(G14-F14))) -> 0.037003238 | J14: =EXP(-(I14+Inputs!$B$9)*B14) -> 0.96664919
A15: 12 | B15: =A15/Inputs!$B$6 -> 1 | C15: =IF(B15<=INDEX(YieldCurve!$A$4:$A$63,1),1,IF(B15>=INDEX(YieldCurve!$A$4:$A$63,ROWS(YieldCurve!$A$4:$A$63)),ROWS(YieldCurve!$A$4:$A$63)-1,MATCH(B15,YieldCurve!$A$4:$A$63,1))) -> 2 | D15: =INDEX(YieldCurve!$A$4:$A$63,C15) -> 1 | E15: =INDEX(YieldCurve!$A$4:$A$63,C15+1) -> 1.5 | F15: =INDEX(YieldCurve!$B$4:$B$63,C15) -> 0.0369537 | G15: =INDEX(YieldCurve!$B$4:$B$63,C15+1) -> 0.03725465 | H15: =IF(E15=D15,0,(B15-D15)/(E15-D15)) -> 0 | I15: =IF(B15<=INDEX(YieldCurve!$A$4:$A$63,1),INDEX(YieldCurve!$B$4:$B$63,1),IF(B15>=INDEX(YieldCurve!$A$4:$A$63,ROWS(YieldCurve!$A$4:$A$63)),INDEX(YieldCurve!$B$4:$B$63,ROWS(YieldCurve!$B$4:$B$63)),F15+H15*(G15-F15))) -> 0.0369537 | J15: =EXP(-(I15+Inputs!$B$9)*B15) -> 0.96372075
... A543: 540 | B543: =A543/Inputs!$B$6 -> 45 | C543: =IF(B543<=INDEX(YieldCurve!$A$4:$A$63,1),1,IF(B543>=INDEX(YieldCurve!$A$4:$A$63,ROWS(YieldCurve!$A$4:$A$63)),ROWS(YieldCurve!$A$4:$A$63)-1,MATCH(B543,YieldCurve!$A$4:$A$63,1))) -> 59 | D543: =INDEX(YieldCurve!$A$4:$A$63,C543) -> 29.5 | E543: =INDEX(YieldCurve!$A$4:$A$63,C543+1) -> 30 | F543: =INDEX(YieldCurve!$B$4:$B$63,C543) -> 0.04947242 | G543: =INDEX(YieldCurve!$B$4:$B$63,C543+1) -> 0.04945471 | H543: =IF(E543=D543,0,(B543-D543)/(E543-D543)) -> 31 | I543: =IF(B543<=INDEX(YieldCurve!$A$4:$A$63,1),INDEX(YieldCurve!$B$4:$B$63,1),IF(B543>=INDEX(YieldCurve!$A$4:$A$63,ROWS(YieldCurve!$A$4:$A$63)),INDEX(YieldCurve!$B$4:$B$63,ROWS(YieldCurve!$B$4:$B$63)),F543+H543*(G543-F543))) -> 0.04945471 | J543: =EXP(-(I543+Inputs!$B$9)*B543) -> 0.10801751

Sheet Projection
A1: SPIA Monthly Projection (Formula Driven)
A2: ReserveAtT0 | B2: 0 | C2: =Inputs!$B$3 -> 65 | U2: =X9 -> 1268279
A3: Month | B3: t_years | C3: AttainedAge | D3: IntAge | E3: CalendarYear | F3: MonthlyBenefit | G3: MonthlyExpense | H3: BaseQx2014 | I3: CumMP | J3: QxYear | K3: MuYear | L3: SurvInterval | M3: SurvivalToPay | N3: ZeroRateInterpolated | O3: DiscountFactor | P3: ExpBenefitCF | Q3: ExpExpenseCF | R3: ExpTotalCF | S3: PVBenefitCF | T3: PVExpenseCF | U3: ReserveAfterPayment | W3: Summary
A4: 1 | B4: =A4/Inputs!$B$6 -> 0.083333333 | C4: =Inputs!$B$3+B4 -> 65.083333 | D4: =INT(C4) -> 65 | E4: =Inputs!$B$7+1+INT((A4-1)/Inputs!$B$6) -> 2026 | F4: =Inputs!$B$16 -> 8333.3333 | G4: =Inputs!$B$12 -> 25 | H4: =IFERROR(INDEX(RP2014_Qx!$B:$B,MATCH(D4,RP2014_Qx!$A:$A,0)),"") -> 0.008048 | I4: =SUMIFS(MP2016_Long!$C:$C,MP2016_Long!$A:$A,D4,MP2016_Long!$B:$B,">=2014",MP2016_Long!$B:$B,"<"&E4) -> 0.0639 | J4: =MIN(0.999999,MAX(0,H4*EXP(I4))) -> 0.0085790537 | K4: =-LN(1-J4) -> 0.0086160656 | L4: =EXP(-K4/Inputs!$B$6) -> 0.99928225 | M4: =L4 -> 0.99928225 | N4: =IFERROR(INDEX(MonthlyCurve!$I:$I,MATCH(A4,MonthlyCurve!$A:$A,0)),"") -> 0.03725093 | O4: =IFERROR(INDEX(MonthlyCurve!$J:$J,MATCH(A4,MonthlyCurve!$A:$A,0)),"") -> 0.99690057 | P4: =F4*M4 -> 8327.3521 | Q4: =G4*M4 -> 24.982056 | R4: =P4+Q4 -> 8352.3342 | S4: =P4*O4 -> 8301.542 | T4: =Q4*O4 -> 24.904626 | U4: =SUMPRODUCT(R5:R543,O5:O543)/(M4*O4) -> 1264777.6 | W4: PV Benefits | X4: =SUM(S4:S543) -> 1264485.5
A5: 2 | B5: =A5/Inputs!$B$6 -> 0.16666667 | C5: =Inputs!$B$3+B5 -> 65.166667 | D5: =INT(C5) -> 65 | E5: =Inputs!$B$7+1+INT((A5-1)/Inputs!$B$6) -> 2026 | F5: =Inputs!$B$16 -> 8333.3333 | G5: =Inputs!$B$12 -> 25 | H5: =IFERROR(INDEX(RP2014_Qx!$B:$B,MATCH(D5,RP2014_Qx!$A:$A,0)),"") -> 0.008048 | I5: =SUMIFS(MP2016_Long!$C:$C,MP2016_Long!$A:$A,D5,MP2016_Long!$B:$B,">=2014",MP2016_Long!$B:$B,"<"&E5) -> 0.0639 | J5: =MIN(0.999999,MAX(0,H5*EXP(I5))) -> 0.0085790537 | K5: =-LN(1-J5) -> 0.0086160656 | L5: =EXP(-K5/Inputs!$B$6) -> 0.99928225 | M5: =M4*L5 -> 0.99856502 | N5: =IFERROR(INDEX(MonthlyCurve!$I:$I,MATCH(A5,MonthlyCurve!$A:$A,0)),"") -> 0.03725093 | O5: =IFERROR(INDEX(MonthlyCurve!$J:$J,MATCH(A5,MonthlyCurve!$A:$A,0)),"") -> 0.99381074 | P5: =F5*M5 -> 8321.3752 | Q5: =G5*M5 -> 24.964125 | R5: =P5+Q5 -> 8346.3393 | S5: =P5*O5 -> 8269.872 | T5: =Q5*O5 -> 24.809616 | U5: =SUMPRODUCT(R6:R543,O6:O543)/(M5*O5) -> 1261262.8 | W5: PV Monthly Expenses | X5: =SUM(T4:T543) -> 3793.4566
A6: 3 | B6: =A6/Inputs!$B$6 -> 0.25 | C6: =Inputs!$B$3+B6 -> 65.25 | D6: =INT(C6) -> 65 | E6: =Inputs!$B$7+1+INT((A6-1)/Inputs!$B$6) -> 2026 | F6: =Inputs!$B$16 -> 8333.3333 | G6: =Inputs!$B$12 -> 25 | H6: =IFERROR(INDEX(RP2014_Qx!$B:$B,MATCH(D6,RP2014_Qx!$A:$A,0)),"") -> 0.008048 | I6: =SUMIFS(MP2016_Long!$C:$C,MP2016_Long!$A:$A,D6,MP2016_Long!$B:$B,">=2014",MP2016_Long!$B:$B,"<"&E6) -> 0.0639 | J6: =MIN(0.999999,MAX(0,H6*EXP(I6))) -> 0.0085790537 | K6: =-LN(1-J6) -> 0.0086160656 | L6: =EXP(-K6/Inputs!$B$6) -> 0.99928225 | M6: =M5*L6 -> 0.9978483 | N6: =IFERROR(INDEX(MonthlyCurve!$I:$I,MATCH(A6,MonthlyCurve!$A:$A,0)),"") -> 0.03725093 | O6: =IFERROR(INDEX(MonthlyCurve!$J:$J,MATCH(A6,MonthlyCurve!$A:$A,0)),"") -> 0.9907305 | P6: =F6*M6 -> 8315.4025 | Q6: =G6*M6 -> 24.946208 | R6: =P6+Q6 -> 8340.3487 | S6: =P6*O6 -> 8238.3229 | T6: =Q6*O6 -> 24.714969 | U6: =SUMPRODUCT(R7:R543,O7:O543)/(M6*O6) -> 1257734.6 | W6: Annuity Factor | X6: =SUMPRODUCT(M4:M543,O4:O543) -> 151.73826
A7: 4 | B7: =A7/Inputs!$B$6 -> 0.33333333 | C7: =Inputs!$B$3+B7 -> 65.333333 | D7: =INT(C7) -> 65 | E7: =Inputs!$B$7+1+INT((A7-1)/Inputs!$B$6) -> 2026 | F7: =Inputs!$B$16 -> 8333.3333 | G7: =Inputs!$B$12 -> 25 | H7: =IFERROR(INDEX(RP2014_Qx!$B:$B,MATCH(D7,RP2014_Qx!$A:$A,0)),"") -> 0.008048 | I7: =SUMIFS(MP2016_Long!$C:$C,MP2016_Long!$A:$A,D7,MP2016_Long!$B:$B,">=2014",MP2016_Long!$B:$B,"<"&E7) -> 0.0639 | J7: =MIN(0.999999,MAX(0,H7*EXP(I7))) -> 0.0085790537 | K7: =-LN(1-J7) -> 0.0086160656 | L7: =EXP(-K7/Inputs!$B$6) -> 0.99928225 | M7: =M6*L7 -> 0.9971321 | N7: =IFERROR(INDEX(MonthlyCurve!$I:$I,MATCH(A7,MonthlyCurve!$A:$A,0)),"") -> 0.03725093 | O7: =IFERROR(INDEX(MonthlyCurve!$J:$J,MATCH(A7,MonthlyCurve!$A:$A,0)),"") -> 0.9876598 | P7: =F7*M7 -> 8309.4342 | Q7: =G7*M7 -> 24.928302 | R7: =P7+Q7 -> 8334.3625 | S7: =P7*O7 -> 8206.894 | T7: =Q7*O7 -> 24.620682 | U7: =SUMPRODUCT(R8:R543,O8:O543)/(M7*O7) -> 1254192.8 | W7: PV Monthly Total | X7: =X4+X5 -> 1268279
A8: 5 | B8: =A8/Inputs!$B$6 -> 0.41666667 | C8: =Inputs!$B$3+B8 -> 65.416667 | D8: =INT(C8) -> 65 | E8: =Inputs!$B$7+1+INT((A8-1)/Inputs!$B$6) -> 2026 | F8: =Inputs!$B$16 -> 8333.3333 | G8: =Inputs!$B$12 -> 25 | H8: =IFERROR(INDEX(RP2014_Qx!$B:$B,MATCH(D8,RP2014_Qx!$A:$A,0)),"") -> 0.008048 | I8: =SUMIFS(MP2016_Long!$C:$C,MP2016_Long!$A:$A,D8,MP2016_Long!$B:$B,">=2014",MP2016_Long!$B:$B,"<"&E8) -> 0.0639 | J8: =MIN(0.999999,MAX(0,H8*EXP(I8))) -> 0.0085790537 | K8: =-LN(1-J8) -> 0.0086160656 | L8: =EXP(-K8/Inputs!$B$6) -> 0.99928225 | M8: =M7*L8 -> 0.99641641 | N8: =IFERROR(INDEX(MonthlyCurve!$I:$I,MATCH(A8,MonthlyCurve!$A:$A,0)),"") -> 0.03725093 | O8: =IFERROR(INDEX(MonthlyCurve!$J:$J,MATCH(A8,MonthlyCurve!$A:$A,0)),"") -> 0.98459861 | P8: =F8*M8 -> 8303.4701 | Q8: =G8*M8 -> 24.91041 | R8: =P8+Q8 -> 8328.3805 | S8: =P8*O8 -> 8175.5851 | T8: =Q8*O8 -> 24.526755 | U8: =SUMPRODUCT(R9:R543,O9:O543)/(M8*O8) -> 1250637.5 | W8: Single Premium | X8: =(Inputs!$B$10+X7)/(1-Inputs!$B$11) -> 1281342.4
A9: 6 | B9: =A9/Inputs!$B$6 -> 0.5 | C9: =Inputs!$B$3+B9 -> 65.5 | D9: =INT(C9) -> 65 | E9: =Inputs!$B$7+1+INT((A9-1)/Inputs!$B$6) -> 2026 | F9: =Inputs!$B$16 -> 8333.3333 | G9: =Inputs!$B$12 -> 25 | H9: =IFERROR(INDEX(RP2014_Qx!$B:$B,MATCH(D9,RP2014_Qx!$A:$A,0)),"") -> 0.008048 | I9: =SUMIFS(MP2016_Long!$C:$C,MP2016_Long!$A:$A,D9,MP2016_Long!$B:$B,">=2014",MP2016_Long!$B:$B,"<"&E9) -> 0.0639 | J9: =MIN(0.999999,MAX(0,H9*EXP(I9))) -> 0.0085790537 | K9: =-LN(1-J9) -> 0.0086160656 | L9: =EXP(-K9/Inputs!$B$6) -> 0.99928225 | M9: =M8*L9 -> 0.99570123 | N9: =IFERROR(INDEX(MonthlyCurve!$I:$I,MATCH(A9,MonthlyCurve!$A:$A,0)),"") -> 0.03725093 | O9: =IFERROR(INDEX(MonthlyCurve!$J:$J,MATCH(A9,MonthlyCurve!$A:$A,0)),"") -> 0.98154692 | P9: =F9*M9 -> 8297.5103 | Q9: =G9*M9 -> 24.892531 | R9: =P9+Q9 -> 8322.4028 | S9: =P9*O9 -> 8144.3956 | T9: =Q9*O9 -> 24.433187 | U9: =SUMPRODUCT(R10:R543,O10:O543)/(M9*O9) -> 1247068.5 | W9: Reserve at t=0 | X9: =X7 -> 1268279
A10: 7 | B10: =A10/Inputs!$B$6 -> 0.58333333 | C10: =Inputs!$B$3+B10 -> 65.583333 | D10: =INT(C10) -> 65 | E10: =Inputs!$B$7+1+INT((A10-1)/Inputs!$B$6) -> 2026 | F10: =Inputs!$B$16 -> 8333.3333 | G10: =Inputs!$B$12 -> 25 | H10: =IFERROR(INDEX(RP2014_Qx!$B:$B,MATCH(D10,RP2014_Qx!$A:$A,0)),"") -> 0.008048 | I10: =SUMIFS(MP2016_Long!$C:$C,MP2016_Long!$A:$A,D10,MP2016_Long!$B:$B,">=2014",MP2016_Long!$B:$B,"<"&E10) -> 0.0639 | J10: =MIN(0.999999,MAX(0,H10*EXP(I10))) -> 0.0085790537 | K10: =-LN(1-J10) -> 0.0086160656 | L10: =EXP(-K10/Inputs!$B$6) -> 0.99928225 | M10: =M9*L10 -> 0.99498657 | N10: =IFERROR(INDEX(MonthlyCurve!$I:$I,MATCH(A10,MonthlyCurve!$A:$A,0)),"") -> 0.037201392 | O10: =IFERROR(INDEX(MonthlyCurve!$J:$J,MATCH(A10,MonthlyCurve!$A:$A,0)),"") -> 0.97853296 | P10: =F10*M10 -> 8291.5548 | Q10: =G10*M10 -> 24.874664 | R10: =P10+Q10 -> 8316.4294 | S10: =P10*O10 -> 8113.5596 | T10: =Q10*O10 -> 24.340679 | U10: =SUMPRODUCT(R11:R543,O11:O543)/(M10*O10) -> 1243449.8
A11: 8 | B11: =A11/Inputs!$B$6 -> 0.66666667 | C11: =Inputs!$B$3+B11 -> 65.666667 | D11: =INT(C11) -> 65 | E11: =Inputs!$B$7+1+INT((A11-1)/Inputs!$B$6) -> 2026 | F11: =Inputs!$B$16 -> 8333.3333 | G11: =Inputs!$B$12 -> 25 | H11: =IFERROR(INDEX(RP2014_Qx!$B:$B,MATCH(D11,RP2014_Qx!$A:$A,0)),"") -> 0.008048 | I11: =SUMIFS(MP2016_Long!$C:$C,MP2016_Long!$A:$A,D11,MP2016_Long!$B:$B,">=2014",MP2016_Long!$B:$B,"<"&E11) -> 0.0639 | J11: =MIN(0.999999,MAX(0,H11*EXP(I11))) -> 0.0085790537 | K11: =-LN(1-J11) -> 0.0086160656 | L11: =EXP(-K11/Inputs!$B$6) -> 0.99928225 | M11: =M10*L11 -> 0.99427242 | N11: =IFERROR(INDEX(MonthlyCurve!$I:$I,MATCH(A11,MonthlyCurve!$A:$A,0)),"") -> 0.037151853 | O11: =IFERROR(INDEX(MonthlyCurve!$J:$J,MATCH(A11,MonthlyCurve!$A:$A,0)),"") -> 0.97553631 | P11: =F11*M11 -> 8285.6035 | Q11: =G11*M11 -> 24.856811 | R11: =P11+Q11 -> 8310.4603 | S11: =P11*O11 -> 8082.907 | T11: =Q11*O11 -> 24.248721 | U11: =SUMPRODUCT(R12:R543,O12:O543)/(M11*O11) -> 1239806.9
A12: 9 | B12: =A12/Inputs!$B$6 -> 0.75 | C12: =Inputs!$B$3+B12 -> 65.75 | D12: =INT(C12) -> 65 | E12: =Inputs!$B$7+1+INT((A12-1)/Inputs!$B$6) -> 2026 | F12: =Inputs!$B$16 -> 8333.3333 | G12: =Inputs!$B$12 -> 25 | H12: =IFERROR(INDEX(RP2014_Qx!$B:$B,MATCH(D12,RP2014_Qx!$A:$A,0)),"") -> 0.008048 | I12: =SUMIFS(MP2016_Long!$C:$C,MP2016_Long!$A:$A,D12,MP2016_Long!$B:$B,">=2014",MP2016_Long!$B:$B,"<"&E12) -> 0.0639 | J12: =MIN(0.999999,MAX(0,H12*EXP(I12))) -> 0.0085790537 | K12: =-LN(1-J12) -> 0.0086160656 | L12: =EXP(-K12/Inputs!$B$6) -> 0.99928225 | M12: =M11*L12 -> 0.99355878 | N12: =IFERROR(INDEX(MonthlyCurve!$I:$I,MATCH(A12,MonthlyCurve!$A:$A,0)),"") -> 0.037102315 | O12: =IFERROR(INDEX(MonthlyCurve!$J:$J,MATCH(A12,MonthlyCurve!$A:$A,0)),"") -> 0.97255686 | P12: =F12*M12 -> 8279.6565 | Q12: =G12*M12 -> 24.83897 | R12: =P12+Q12 -> 8304.4955 | S12: =P12*O12 -> 8052.4368 | T12: =Q12*O12 -> 24.15731 | U12: =SUMPRODUCT(R13:R543,O13:O543)/(M12*O12) -> 1236140
A13: 10 | B13: =A13/Inputs!$B$6 -> 0.83333333 | C13: =Inputs!$B$3+B13 -> 65.833333 | D13: =INT(C13) -> 65 | E13: =Inputs!$B$7+1+INT((A13-1)/Inputs!$B$6) -> 2026 | F13: =Inputs!$B$16 -> 8333.3333 | G13: =Inputs!$B$12 -> 25 | H13: =IFERROR(INDEX(RP2014_Qx!$B:$B,MATCH(D13,RP2014_Qx!$A:$A,0)),"") -> 0.008048 | I13: =SUMIFS(MP2016_Long!$C:$C,MP2016_Long!$A:$A,D13,MP2016_Long!$B:$B,">=2014",MP2016_Long!$B:$B,"<"&E13) -> 0.0639 | J13: =MIN(0.999999,MAX(0,H13*EXP(I13))) -> 0.0085790537 | K13: =-LN(1-J13) -> 0.0086160656 | L13: =EXP(-K13/Inputs!$B$6) -> 0.99928225 | M13: =M12*L13 -> 0.99284566 | N13: =IFERROR(INDEX(MonthlyCurve!$I:$I,MATCH(A13,MonthlyCurve!$A:$A,0)),"") -> 0.037052777 | O13: =IFERROR(INDEX(MonthlyCurve!$J:$J,MATCH(A13,MonthlyCurve!$A:$A,0)),"") -> 0.96959452 | P13: =F13*M13 -> 8273.7138 | Q13: =G13*M13 -> 24.821142 | R13: =P13+Q13 -> 8298.535 | S13: =P13*O13 -> 8022.1476 | T13: =Q13*O13 -> 24.066443 | U13: =SUMPRODUCT(R14:R543,O14:O543)/(M13*O13) -> 1232449
A14: 11 | B14: =A14/Inputs!$B$6 -> 0.91666667 | C14: =Inputs!$B$3+B14 -> 65.916667 | D14: =INT(C14) -> 65 | E14: =Inputs!$B$7+1+INT((A14-1)/Inputs!$B$6) -> 2026 | F14: =Inputs!$B$16 -> 8333.3333 | G14: =Inputs!$B$12 -> 25 | H14: =IFERROR(INDEX(RP2014_Qx!$B:$B,MATCH(D14,RP2014_Qx!$A:$A,0)),"") -> 0.008048 | I14: =SUMIFS(MP2016_Long!$C:$C,MP2016_Long!$A:$A,D14,MP2016_Long!$B:$B,">=2014",MP2016_Long!$B:$B,"<"&E14) -> 0.0639 | J14: =MIN(0.999999,MAX(0,H14*EXP(I14))) -> 0.0085790537 | K14: =-LN(1-J14) -> 0.0086160656 | L14: =EXP(-K14/Inputs!$B$6) -> 0.99928225 | M14: =M13*L14 -> 0.99213305 | N14: =IFERROR(INDEX(MonthlyCurve!$I:$I,MATCH(A14,MonthlyCurve!$A:$A,0)),"") -> 0.037003238 | O14: =IFERROR(INDEX(MonthlyCurve!$J:$J,MATCH(A14,MonthlyCurve!$A:$A,0)),"") -> 0.96664919 | P14: =F14*M14 -> 8267.7754 | Q14: =G14*M14 -> 24.803326 | R14: =P14+Q14 -> 8292.5787 | S14: =P14*O14 -> 7992.0384 | T14: =Q14*O14 -> 23.976115 | U14: =SUMPRODUCT(R15:R543,O15:O543)/(M14*O14) -> 1228733.8
A15: 12 | B15: =A15/Inputs!$B$6 -> 1 | C15: =Inputs!$B$3+B15 -> 66 | D15: =INT(C15) -> 66 | E15: =Inputs!$B$7+1+INT((A15-1)/Inputs!$B$6) -> 2026 | F15: =Inputs!$B$16 -> 8333.3333 | G15: =Inputs!$B$12 -> 25 | H15: =IFERROR(INDEX(RP2014_Qx!$B:$B,MATCH(D15,RP2014_Qx!$A:$A,0)),"") -> 0.008821 | I15: =SUMIFS(MP2016_Long!$C:$C,MP2016_Long!$A:$A,D15,MP2016_Long!$B:$B,">=2014",MP2016_Long!$B:$B,"<"&E15) -> 0.0667 | J15: =MIN(0.999999,MAX(0,H15*EXP(I15))) -> 0.0094294262 | K15: =-LN(1-J15) -> 0.0094741647 | L15: =EXP(-K15/Inputs!$B$6) -> 0.9992108 | M15: =M14*L15 -> 0.99135005 | N15: =IFERROR(INDEX(MonthlyCurve!$I:$I,MATCH(A15,MonthlyCurve!$A:$A,0)),"") -> 0.0369537 | O15: =IFERROR(INDEX(MonthlyCurve!$J:$J,MATCH(A15,MonthlyCurve!$A:$A,0)),"") -> 0.96372075 | P15: =F15*M15 -> 8261.2505 | Q15: =G15*M15 -> 24.783751 | R15: =P15+Q15 -> 8286.0342 | S15: =P15*O15 -> 7961.5385 | T15: =Q15*O15 -> 23.884616 | U15: =SUMPRODUCT(R16:R543,O16:O543)/(M15*O15) -> 1225082.6
A16: 13 | B16: =A16/Inputs!$B$6 -> 1.0833333 | C16: =Inputs!$B$3+B16 -> 66.083333 | D16: =INT(C16) -> 66 | E16: =Inputs!$B$7+1+INT((A16-1)/Inputs!$B$6) -> 2027 | F16: =Inputs!$B$16 -> 8333.3333 | G16: =Inputs!$B$12 -> 25 | H16: =IFERROR(INDEX(RP2014_Qx!$B:$B,MATCH(D16,RP2014_Qx!$A:$A,0)),"") -> 0.008821 | I16: =SUMIFS(MP2016_Long!$C:$C,MP2016_Long!$A:$A,D16,MP2016_Long!$B:$B,">=2014",MP2016_Long!$B:$B,"<"&E16) -> 0.0767 | J16: =MIN(0.999999,MAX(0,H16*EXP(I16))) -> 0.0095241935 | K16: =-LN(1-J16) -> 0.0095698387 | L16: =EXP(-K16/Inputs!$B$6) -> 0.99920283 | M16: =M15*L16 -> 0.99055978 | N16: =IFERROR(INDEX(MonthlyCurve!$I:$I,MATCH(A16,MonthlyCurve!$A:$A,0)),"") -> 0.037003858 | O16: =IFERROR(INDEX(MonthlyCurve!$J:$J,MATCH(A16,MonthlyCurve!$A:$A,0)),"") -> 0.96070536 | P16: =F16*M16 -> 8254.6648 | Q16: =G16*M16 -> 24.763995 | R16: =P16+Q16 -> 8279.4288 | S16: =P16*O16 -> 7930.3008 | T16: =Q16*O16 -> 23.790902 | U16: =SUMPRODUCT(R17:R543,O17:O543)/(M16*O16) -> 1221549.9
A17: 14 | B17: =A17/Inputs!$B$6 -> 1.1666667 | C17: =Inputs!$B$3+B17 -> 66.166667 | D17: =INT(C17) -> 66 | E17: =Inputs!$B$7+1+INT((A17-1)/Inputs!$B$6) -> 2027 | F17: =Inputs!$B$16 -> 8333.3333 | G17: =Inputs!$B$12 -> 25 | H17: =IFERROR(INDEX(RP2014_Qx!$B:$B,MATCH(D17,RP2014_Qx!$A:$A,0)),"") -> 0.008821 | I17: =SUMIFS(MP2016_Long!$C:$C,MP2016_Long!$A:$A,D17,MP2016_Long!$B:$B,">=2014",MP2016_Long!$B:$B,"<"&E17) -> 0.0767 | J17: =MIN(0.999999,MAX(0,H17*EXP(I17))) -> 0.0095241935 | K17: =-LN(1-J17) -> 0.0095698387 | L17: =EXP(-K17/Inputs!$B$6) -> 0.99920283 | M17: =M16*L17 -> 0.98977014 | N17: =IFERROR(INDEX(MonthlyCurve!$I:$I,MATCH(A17,MonthlyCurve!$A:$A,0)),"") -> 0.037054017 | O17: =IFERROR(INDEX(MonthlyCurve!$J:$J,MATCH(A17,MonthlyCurve!$A:$A,0)),"") -> 0.9576914 | P17: =F17*M17 -> 8248.0845 | Q17: =G17*M17 -> 24.744253 | R17: =P17+Q17 -> 8272.8287 | S17: =P17*O17 -> 7899.1195 | T17: =Q17*O17 -> 23.697359 | U17: =SUMPRODUCT(R18:R543,O18:O543)/(M17*O17) -> 1218013.5
A18: 15 | B18: =A18/Inputs!$B$6 -> 1.25 | C18: =Inputs!$B$3+B18 -> 66.25 | D18: =INT(C18) -> 66 | E18: =Inputs!$B$7+1+INT((A18-1)/Inputs!$B$6) -> 2027 | F18: =Inputs!$B$16 -> 8333.3333 | G18: =Inputs!$B$12 -> 25 | H18: =IFERROR(INDEX(RP2014_Qx!$B:$B,MATCH(D18,RP2014_Qx!$A:$A,0)),"") -> 0.008821 | I18: =SUMIFS(MP2016_Long!$C:$C,MP2016_Long!$A:$A,D18,MP2016_Long!$B:$B,">=2014",MP2016_Long!$B:$B,"<"&E18) -> 0.0767 | J18: =MIN(0.999999,MAX(0,H18*EXP(I18))) -> 0.0095241935 | K18: =-LN(1-J18) -> 0.0095698387 | L18: =EXP(-K18/Inputs!$B$6) -> 0.99920283 | M18: =M17*L18 -> 0.98898112 | N18: =IFERROR(INDEX(MonthlyCurve!$I:$I,MATCH(A18,MonthlyCurve!$A:$A,0)),"") -> 0.037104175 | O18: =IFERROR(INDEX(MonthlyCurve!$J:$J,MATCH(A18,MonthlyCurve!$A:$A,0)),"") -> 0.95467891 | P18: =F18*M18 -> 8241.5094 | Q18: =G18*M18 -> 24.724528 | R18: =P18+Q18 -> 8266.2339 | S18: =P18*O18 -> 7867.9951 | T18: =Q18*O18 -> 23.603985 | U18: =SUMPRODUCT(R19:R543,O19:O543)/(M18*O18) -> 1214473.4
A19: 16 | B19: =A19/Inputs!$B$6 -> 1.3333333 | C19: =Inputs!$B$3+B19 -> 66.333333 | D19: =INT(C19) -> 66 | E19: =Inputs!$B$7+1+INT((A19-1)/Inputs!$B$6) -> 2027 | F19: =Inputs!$B$16 -> 8333.3333 | G19: =Inputs!$B$12 -> 25 | H19: =IFERROR(INDEX(RP2014_Qx!$B:$B,MATCH(D19,RP2014_Qx!$A:$A,0)),"") -> 0.008821 | I19: =SUMIFS(MP2016_Long!$C:$C,MP2016_Long!$A:$A,D19,MP2016_Long!$B:$B,">=2014",MP2016_Long!$B:$B,"<"&E19) -> 0.0767 | J19: =MIN(0.999999,MAX(0,H19*EXP(I19))) -> 0.0095241935 | K19: =-LN(1-J19) -> 0.0095698387 | L19: =EXP(-K19/Inputs!$B$6) -> 0.99920283 | M19: =M18*L19 -> 0.98819274 | N19: =IFERROR(INDEX(MonthlyCurve!$I:$I,MATCH(A19,MonthlyCurve!$A:$A,0)),"") -> 0.037154333 | O19: =IFERROR(INDEX(MonthlyCurve!$J:$J,MATCH(A19,MonthlyCurve!$A:$A,0)),"") -> 0.95166794 | P19: =F19*M19 -> 8234.9395 | Q19: =G19*M19 -> 24.704818 | R19: =P19+Q19 -> 8259.6443 | S19: =P19*O19 -> 7836.9279 | T19: =Q19*O19 -> 23.510784 | U19: =SUMPRODUCT(R20:R543,O20:O543)/(M19*O19) -> 1210929.5
A20: 17 | B20: =A20/Inputs!$B$6 -> 1.4166667 | C20: =Inputs!$B$3+B20 -> 66.416667 | D20: =INT(C20) -> 66 | E20: =Inputs!$B$7+1+INT((A20-1)/Inputs!$B$6) -> 2027 | F20: =Inputs!$B$16 -> 8333.3333 | G20: =Inputs!$B$12 -> 25 | H20: =IFERROR(INDEX(RP2014_Qx!$B:$B,MATCH(D20,RP2014_Qx!$A:$A,0)),"") -> 0.008821 | I20: =SUMIFS(MP2016_Long!$C:$C,MP2016_Long!$A:$A,D20,MP2016_Long!$B:$B,">=2014",MP2016_Long!$B:$B,"<"&E20) -> 0.0767 | J20: =MIN(0.999999,MAX(0,H20*EXP(I20))) -> 0.0095241935 | K20: =-LN(1-J20) -> 0.0095698387 | L20: =EXP(-K20/Inputs!$B$6) -> 0.99920283 | M20: =M19*L20 -> 0.98740498 | N20: =IFERROR(INDEX(MonthlyCurve!$I:$I,MATCH(A20,MonthlyCurve!$A:$A,0)),"") -> 0.037204492 | O20: =IFERROR(INDEX(MonthlyCurve!$J:$J,MATCH(A20,MonthlyCurve!$A:$A,0)),"") -> 0.94865853 | P20: =F20*M20 -> 8228.3749 | Q20: =G20*M20 -> 24.685125 | R20: =P20+Q20 -> 8253.06 | S20: =P20*O20 -> 7805.918 | T20: =Q20*O20 -> 23.417754 | U20: =SUMPRODUCT(R21:R543,O21:O543)/(M20*O20) -> 1207381.8
A21: 18 | B21: =A21/Inputs!$B$6 -> 1.5 | C21: =Inputs!$B$3+B21 -> 66.5 | D21: =INT(C21) -> 66 | E21: =Inputs!$B$7+1+INT((A21-1)/Inputs!$B$6) -> 2027 | F21: =Inputs!$B$16 -> 8333.3333 | G21: =Inputs!$B$12 -> 25 | H21: =IFERROR(INDEX(RP2014_Qx!$B:$B,MATCH(D21,RP2014_Qx!$A:$A,0)),"") -> 0.008821 | I21: =SUMIFS(MP2016_Long!$C:$C,MP2016_Long!$A:$A,D21,MP2016_Long!$B:$B,">=2014",MP2016_Long!$B:$B,"<"&E21) -> 0.0767 | J21: =MIN(0.999999,MAX(0,H21*EXP(I21))) -> 0.0095241935 | K21: =-LN(1-J21) -> 0.0095698387 | L21: =EXP(-K21/Inputs!$B$6) -> 0.99920283 | M21: =M20*L21 -> 0.98661785 | N21: =IFERROR(INDEX(MonthlyCurve!$I:$I,MATCH(A21,MonthlyCurve!$A:$A,0)),"") -> 0.03725465 | O21: =IFERROR(INDEX(MonthlyCurve!$J:$J,MATCH(A21,MonthlyCurve!$A:$A,0)),"") -> 0.94565074 | P21: =F21*M21 -> 8221.8155 | Q21: =G21*M21 -> 24.665446 | R21: =P21+Q21 -> 8246.4809 | S21: =P21*O21 -> 7774.9659 | T21: =Q21*O21 -> 23.324898 | U21: =SUMPRODUCT(R22:R543,O22:O543)/(M21*O21) -> 1203830
A22: 19 | B22: =A22/Inputs!$B$6 -> 1.5833333 | C22: =Inputs!$B$3+B22 -> 66.583333 | D22: =INT(C22) -> 66 | E22: =Inputs!$B$7+1+INT((A22-1)/Inputs!$B$6) -> 2027 | F22: =Inputs!$B$16 -> 8333.3333 | G22: =Inputs!$B$12 -> 25 | H22: =IFERROR(INDEX(RP2014_Qx!$B:$B,MATCH(D22,RP2014_Qx!$A:$A,0)),"") -> 0.008821 | I22: =SUMIFS(MP2016_Long!$C:$C,MP2016_Long!$A:$A,D22,MP2016_Long!$B:$B,">=2014",MP2016_Long!$B:$B,"<"&E22) -> 0.0767 | J22: =MIN(0.999999,MAX(0,H22*EXP(I22))) -> 0.0095241935 | K22: =-LN(1-J22) -> 0.0095698387 | L22: =EXP(-K22/Inputs!$B$6) -> 0.99920283 | M22: =M21*L22 -> 0.98583135 | N22: =IFERROR(INDEX(MonthlyCurve!$I:$I,MATCH(A22,MonthlyCurve!$A:$A,0)),"") -> 0.037304987 | O22: =IFERROR(INDEX(MonthlyCurve!$J:$J,MATCH(A22,MonthlyCurve!$A:$A,0)),"") -> 0.94264434 | P22: =F22*M22 -> 8215.2613 | Q22: =G22*M22 -> 24.645784 | R22: =P22+Q22 -> 8239.9071 | S22: =P22*O22 -> 7744.0695 | T22: =Q22*O22 -> 23.232209 | U22: =SUMPRODUCT(R23:R543,O23:O543)/(M22*O22) -> 1200274.6
A23: 20 | B23: =A23/Inputs!$B$6 -> 1.6666667 | C23: =Inputs!$B$3+B23 -> 66.666667 | D23: =INT(C23) -> 66 | E23: =Inputs!$B$7+1+INT((A23-1)/Inputs!$B$6) -> 2027 | F23: =Inputs!$B$16 -> 8333.3333 | G23: =Inputs!$B$12 -> 25 | H23: =IFERROR(INDEX(RP2014_Qx!$B:$B,MATCH(D23,RP2014_Qx!$A:$A,0)),"") -> 0.008821 | I23: =SUMIFS(MP2016_Long!$C:$C,MP2016_Long!$A:$A,D23,MP2016_Long!$B:$B,">=2014",MP2016_Long!$B:$B,"<"&E23) -> 0.0767 | J23: =MIN(0.999999,MAX(0,H23*EXP(I23))) -> 0.0095241935 | K23: =-LN(1-J23) -> 0.0095698387 | L23: =EXP(-K23/Inputs!$B$6) -> 0.99920283 | M23: =M22*L23 -> 0.98504548 | N23: =IFERROR(INDEX(MonthlyCurve!$I:$I,MATCH(A23,MonthlyCurve!$A:$A,0)),"") -> 0.037355323 | O23: =IFERROR(INDEX(MonthlyCurve!$J:$J,MATCH(A23,MonthlyCurve!$A:$A,0)),"") -> 0.93963961 | P23: =F23*M23 -> 8208.7123 | Q23: =G23*M23 -> 24.626137 | R23: =P23+Q23 -> 8233.3385 | S23: =P23*O23 -> 7713.2312 | T23: =Q23*O23 -> 23.139694 | U23: =SUMPRODUCT(R24:R543,O24:O543)/(M23*O23) -> 1196715.1
A24: 21 | B24: =A24/Inputs!$B$6 -> 1.75 | C24: =Inputs!$B$3+B24 -> 66.75 | D24: =INT(C24) -> 66 | E24: =Inputs!$B$7+1+INT((A24-1)/Inputs!$B$6) -> 2027 | F24: =Inputs!$B$16 -> 8333.3333 | G24: =Inputs!$B$12 -> 25 | H24: =IFERROR(INDEX(RP2014_Qx!$B:$B,MATCH(D24,RP2014_Qx!$A:$A,0)),"") -> 0.008821 | I24: =SUMIFS(MP2016_Long!$C:$C,MP2016_Long!$A:$A,D24,MP2016_Long!$B:$B,">=2014",MP2016_Long!$B:$B,"<"&E24) -> 0.0767 | J24: =MIN(0.999999,MAX(0,H24*EXP(I24))) -> 0.0095241935 | K24: =-LN(1-J24) -> 0.0095698387 | L24: =EXP(-K24/Inputs!$B$6) -> 0.99920283 | M24: =M23*L24 -> 0.98426023 | N24: =IFERROR(INDEX(MonthlyCurve!$I:$I,MATCH(A24,MonthlyCurve!$A:$A,0)),"") -> 0.03740566 | O24: =IFERROR(INDEX(MonthlyCurve!$J:$J,MATCH(A24,MonthlyCurve!$A:$A,0)),"") -> 0.9366366 | P24: =F24*M24 -> 8202.1686 | Q24: =G24*M24 -> 24.606506 | R24: =P24+Q24 -> 8226.7751 | S24: =P24*O24 -> 7682.4513 | T24: =Q24*O24 -> 23.047354 | U24: =SUMPRODUCT(R25:R543,O25:O543)/(M24*O24) -> 1193151.4
A25: 22 | B25: =A25/Inputs!$B$6 -> 1.8333333 | C25: =Inputs!$B$3+B25 -> 66.833333 | D25: =INT(C25) -> 66 | E25: =Inputs!$B$7+1+INT((A25-1)/Inputs!$B$6) -> 2027 | F25: =Inputs!$B$16 -> 8333.3333 | G25: =Inputs!$B$12 -> 25 | H25: =IFERROR(INDEX(RP2014_Qx!$B:$B,MATCH(D25,RP2014_Qx!$A:$A,0)),"") -> 0.008821 | I25: =SUMIFS(MP2016_Long!$C:$C,MP2016_Long!$A:$A,D25,MP2016_Long!$B:$B,">=2014",MP2016_Long!$B:$B,"<"&E25) -> 0.0767 | J25: =MIN(0.999999,MAX(0,H25*EXP(I25))) -> 0.0095241935 | K25: =-LN(1-J25) -> 0.0095698387 | L25: =EXP(-K25/Inputs!$B$6) -> 0.99920283 | M25: =M24*L25 -> 0.98347561 | N25: =IFERROR(INDEX(MonthlyCurve!$I:$I,MATCH(A25,MonthlyCurve!$A:$A,0)),"") -> 0.037455997 | O25: =IFERROR(INDEX(MonthlyCurve!$J:$J,MATCH(A25,MonthlyCurve!$A:$A,0)),"") -> 0.93363536 | P25: =F25*M25 -> 8195.6301 | Q25: =G25*M25 -> 24.58689 | R25: =P25+Q25 -> 8220.217 | S25: =P25*O25 -> 7651.73 | T25: =Q25*O25 -> 22.95519 | U25: =SUMPRODUCT(R26:R543,O26:O543)/(M25*O25) -> 1189583.5
A26: 23 | B26: =A26/Inputs!$B$6 -> 1.9166667 | C26: =Inputs!$B$3+B26 -> 66.916667 | D26: =INT(C26) -> 66 | E26: =Inputs!$B$7+1+INT((A26-1)/Inputs!$B$6) -> 2027 | F26: =Inputs!$B$16 -> 8333.3333 | G26: =Inputs!$B$12 -> 25 | H26: =IFERROR(INDEX(RP2014_Qx!$B:$B,MATCH(D26,RP2014_Qx!$A:$A,0)),"") -> 0.008821 | I26: =SUMIFS(MP2016_Long!$C:$C,MP2016_Long!$A:$A,D26,MP2016_Long!$B:$B,">=2014",MP2016_Long!$B:$B,"<"&E26) -> 0.0767 | J26: =MIN(0.999999,MAX(0,H26*EXP(I26))) -> 0.0095241935 | K26: =-LN(1-J26) -> 0.0095698387 | L26: =EXP(-K26/Inputs!$B$6) -> 0.99920283 | M26: =M25*L26 -> 0.98269162 | N26: =IFERROR(INDEX(MonthlyCurve!$I:$I,MATCH(A26,MonthlyCurve!$A:$A,0)),"") -> 0.037506333 | O26: =IFERROR(INDEX(MonthlyCurve!$J:$J,MATCH(A26,MonthlyCurve!$A:$A,0)),"") -> 0.93063592 | P26: =F26*M26 -> 8189.0968 | Q26: =G26*M26 -> 24.56729 | R26: =P26+Q26 -> 8213.6641 | S26: =P26*O26 -> 7621.0676 | T26: =Q26*O26 -> 22.863203 | U26: =SUMPRODUCT(R27:R543,O27:O543)/(M26*O26) -> 1186011.3
A27: 24 | B27: =A27/Inputs!$B$6 -> 2 | C27: =Inputs!$B$3+B27 -> 67 | D27: =INT(C27) -> 67 | E27: =Inputs!$B$7+1+INT((A27-1)/Inputs!$B$6) -> 2027 | F27: =Inputs!$B$16 -> 8333.3333 | G27: =Inputs!$B$12 -> 25 | H27: =IFERROR(INDEX(RP2014_Qx!$B:$B,MATCH(D27,RP2014_Qx!$A:$A,0)),"") -> 0.009679 | I27: =SUMIFS(MP2016_Long!$C:$C,MP2016_Long!$A:$A,D27,MP2016_Long!$B:$B,">=2014",MP2016_Long!$B:$B,"<"&E27) -> 0.0809 | J27: =MIN(0.999999,MAX(0,H27*EXP(I27))) -> 0.010494576 | K27: =-LN(1-J27) -> 0.010550033 | L27: =EXP(-K27/Inputs!$B$6) -> 0.99912122 | M27: =M26*L27 -> 0.98182804 | N27: =IFERROR(INDEX(MonthlyCurve!$I:$I,MATCH(A27,MonthlyCurve!$A:$A,0)),"") -> 0.03755667 | O27: =IFERROR(INDEX(MonthlyCurve!$J:$J,MATCH(A27,MonthlyCurve!$A:$A,0)),"") -> 0.92763834 | P27: =F27*M27 -> 8181.9004 | Q27: =G27*M27 -> 24.545701 | R27: =P27+Q27 -> 8206.4461 | S27: =P27*O27 -> 7589.8445 | T27: =Q27*O27 -> 22.769533 | U27: =SUMPRODUCT(R28:R543,O28:O543)/(M27*O27) -> 1182532
A28: 25 | B28: =A28/Inputs!$B$6 -> 2.0833333 | C28: =Inputs!$B$3+B28 -> 67.083333 | D28: =INT(C28) -> 67 | E28: =Inputs!$B$7+1+INT((A28-1)/Inputs!$B$6) -> 2028 | F28: =Inputs!$B$16 -> 8333.3333 | G28: =Inputs!$B$12 -> 25 | H28: =IFERROR(INDEX(RP2014_Qx!$B:$B,MATCH(D28,RP2014_Qx!$A:$A,0)),"") -> 0.009679 | I28: =SUMIFS(MP2016_Long!$C:$C,MP2016_Long!$A:$A,D28,MP2016_Long!$B:$B,">=2014",MP2016_Long!$B:$B,"<"&E28) -> 0.0909 | J28: =MIN(0.999999,MAX(0,H28*EXP(I28))) -> 0.010600049 | K28: =-LN(1-J28) -> 0.010656629 | L28: =EXP(-K28/Inputs!$B$6) -> 0.99911234 | M28: =M27*L28 -> 0.98095651 | N28: =IFERROR(INDEX(MonthlyCurve!$I:$I,MATCH(A28,MonthlyCurve!$A:$A,0)),"") -> 0.037556293 | O28: =IFERROR(INDEX(MonthlyCurve!$J:$J,MATCH(A28,MonthlyCurve!$A:$A,0)),"") -> 0.92474036 | P28: =F28*M28 -> 8174.6376 | Q28: =G28*M28 -> 24.523913 | R28: =P28+Q28 -> 8199.1615 | S28: =P28*O28 -> 7559.4173 | T28: =Q28*O28 -> 22.678252 | U28: =SUMPRODUCT(R29:R543,O29:O543)/(M28*O28) -> 1178933.4
A29: 26 | B29: =A29/Inputs!$B$6 -> 2.1666667 | C29: =Inputs!$B$3+B29 -> 67.166667 | D29: =INT(C29) -> 67 | E29: =Inputs!$B$7+1+INT((A29-1)/Inputs!$B$6) -> 2028 | F29: =Inputs!$B$16 -> 8333.3333 | G29: =Inputs!$B$12 -> 25 | H29: =IFERROR(INDEX(RP2014_Qx!$B:$B,MATCH(D29,RP2014_Qx!$A:$A,0)),"") -> 0.009679 | I29: =SUMIFS(MP2016_Long!$C:$C,MP2016_Long!$A:$A,D29,MP2016_Long!$B:$B,">=2014",MP2016_Long!$B:$B,"<"&E29) -> 0.0909 | J29: =MIN(0.999999,MAX(0,H29*EXP(I29))) -> 0.010600049 | K29: =-LN(1-J29) -> 0.010656629 | L29: =EXP(-K29/Inputs!$B$6) -> 0.99911234 | M29: =M28*L29 -> 0.98008576 | N29: =IFERROR(INDEX(MonthlyCurve!$I:$I,MATCH(A29,MonthlyCurve!$A:$A,0)),"") -> 0.037555917 | O29: =IFERROR(INDEX(MonthlyCurve!$J:$J,MATCH(A29,MonthlyCurve!$A:$A,0)),"") -> 0.92185148 | P29: =F29*M29 -> 8167.3813 | Q29: =G29*M29 -> 24.502144 | R29: =P29+Q29 -> 8191.8835 | S29: =P29*O29 -> 7529.1126 | T29: =Q29*O29 -> 22.587338 | U29: =SUMPRODUCT(R30:R543,O30:O543)/(M29*O29) -> 1175320.3
A30: 27 | B30: =A30/Inputs!$B$6 -> 2.25 | C30: =Inputs!$B$3+B30 -> 67.25 | D30: =INT(C30) -> 67 | E30: =Inputs!$B$7+1+INT((A30-1)/Inputs!$B$6) -> 2028 | F30: =Inputs!$B$16 -> 8333.3333 | G30: =Inputs!$B$12 -> 25 | H30: =IFERROR(INDEX(RP2014_Qx!$B:$B,MATCH(D30,RP2014_Qx!$A:$A,0)),"") -> 0.009679 | I30: =SUMIFS(MP2016_Long!$C:$C,MP2016_Long!$A:$A,D30,MP2016_Long!$B:$B,">=2014",MP2016_Long!$B:$B,"<"&E30) -> 0.0909 | J30: =MIN(0.999999,MAX(0,H30*EXP(I30))) -> 0.010600049 | K30: =-LN(1-J30) -> 0.010656629 | L30: =EXP(-K30/Inputs!$B$6) -> 0.99911234 | M30: =M29*L30 -> 0.97921578 | N30: =IFERROR(INDEX(MonthlyCurve!$I:$I,MATCH(A30,MonthlyCurve!$A:$A,0)),"") -> 0.03755554 | O30: =IFERROR(INDEX(MonthlyCurve!$J:$J,MATCH(A30,MonthlyCurve!$A:$A,0)),"") -> 0.91897169 | P30: =F30*M30 -> 8160.1315 | Q30: =G30*M30 -> 24.480394 | R30: =P30+Q30 -> 8184.6119 | S30: =P30*O30 -> 7498.9298 | T30: =Q30*O30 -> 22.496789 | U30: =SUMPRODUCT(R31:R543,O31:O543)/(M30*O30) -> 1171692.6
A31: 28 | B31: =A31/Inputs!$B$6 -> 2.3333333 | C31: =Inputs!$B$3+B31 -> 67.333333 | D31: =INT(C31) -> 67 | E31: =Inputs!$B$7+1+INT((A31-1)/Inputs!$B$6) -> 2028 | F31: =Inputs!$B$16 -> 8333.3333 | G31: =Inputs!$B$12 -> 25 | H31: =IFERROR(INDEX(RP2014_Qx!$B:$B,MATCH(D31,RP2014_Qx!$A:$A,0)),"") -> 0.009679 | I31: =SUMIFS(MP2016_Long!$C:$C,MP2016_Long!$A:$A,D31,MP2016_Long!$B:$B,">=2014",MP2016_Long!$B:$B,"<"&E31) -> 0.0909 | J31: =MIN(0.999999,MAX(0,H31*EXP(I31))) -> 0.010600049 | K31: =-LN(1-J31) -> 0.010656629 | L31: =EXP(-K31/Inputs!$B$6) -> 0.99911234 | M31: =M30*L31 -> 0.97834657 | N31: =IFERROR(INDEX(MonthlyCurve!$I:$I,MATCH(A31,MonthlyCurve!$A:$A,0)),"") -> 0.037555163 | O31: =IFERROR(INDEX(MonthlyCurve!$J:$J,MATCH(A31,MonthlyCurve!$A:$A,0)),"") -> 0.91610095 | P31: =F31*M31 -> 8152.8881 | Q31: =G31*M31 -> 24.458664 | R31: =P31+Q31 -> 8177.3468 | S31: =P31*O31 -> 7468.8685 | T31: =Q31*O31 -> 22.406606 | U31: =SUMPRODUCT(R32:R543,O32:O543)/(M31*O31) -> 1168050.2
A32: 29 | B32: =A32/Inputs!$B$6 -> 2.4166667 | C32: =Inputs!$B$3+B32 -> 67.416667 | D32: =INT(C32) -> 67 | E32: =Inputs!$B$7+1+INT((A32-1)/Inputs!$B$6) -> 2028 | F32: =Inputs!$B$16 -> 8333.3333 | G32: =Inputs!$B$12 -> 25 | H32: =IFERROR(INDEX(RP2014_Qx!$B:$B,MATCH(D32,RP2014_Qx!$A:$A,0)),"") -> 0.009679 | I32: =SUMIFS(MP2016_Long!$C:$C,MP2016_Long!$A:$A,D32,MP2016_Long!$B:$B,">=2014",MP2016_Long!$B:$B,"<"&E32) -> 0.0909 | J32: =MIN(0.999999,MAX(0,H32*EXP(I32))) -> 0.010600049 | K32: =-LN(1-J32) -> 0.010656629 | L32: =EXP(-K32/Inputs!$B$6) -> 0.99911234 | M32: =M31*L32 -> 0.97747813 | N32: =IFERROR(INDEX(MonthlyCurve!$I:$I,MATCH(A32,MonthlyCurve!$A:$A,0)),"") -> 0.037554787 | O32: =IFERROR(INDEX(MonthlyCurve!$J:$J,MATCH(A32,MonthlyCurve!$A:$A,0)),"") -> 0.91323923 | P32: =F32*M32 -> 8145.6511 | Q32: =G32*M32 -> 24.436953 | R32: =P32+Q32 -> 8170.0881 | S32: =P32*O32 -> 7438.9282 | T32: =Q32*O32 -> 22.316785 | U32: =SUMPRODUCT(R33:R543,O33:O543)/(M32*O32) -> 1164393
A33: 30 | B33: =A33/Inputs!$B$6 -> 2.5 | C33: =Inputs!$B$3+B33 -> 67.5 | D33: =INT(C33) -> 67 | E33: =Inputs!$B$7+1+INT((A33-1)/Inputs!$B$6) -> 2028 | F33: =Inputs!$B$16 -> 8333.3333 | G33: =Inputs!$B$12 -> 25 | H33: =IFERROR(INDEX(RP2014_Qx!$B:$B,MATCH(D33,RP2014_Qx!$A:$A,0)),"") -> 0.009679 | I33: =SUMIFS(MP2016_Long!$C:$C,MP2016_Long!$A:$A,D33,MP2016_Long!$B:$B,">=2014",MP2016_Long!$B:$B,"<"&E33) -> 0.0909 | J33: =MIN(0.999999,MAX(0,H33*EXP(I33))) -> 0.010600049 | K33: =-LN(1-J33) -> 0.010656629 | L33: =EXP(-K33/Inputs!$B$6) -> 0.99911234 | M33: =M32*L33 -> 0.97661047 | N33: =IFERROR(INDEX(MonthlyCurve!$I:$I,MATCH(A33,MonthlyCurve!$A:$A,0)),"") -> 0.03755441 | O33: =IFERROR(INDEX(MonthlyCurve!$J:$J,MATCH(A33,MonthlyCurve!$A:$A,0)),"") -> 0.91038652 | P33: =F33*M33 -> 8138.4206 | Q33: =G33*M33 -> 24.415262 | R33: =P33+Q33 -> 8162.8358 | S33: =P33*O33 -> 7409.1083 | T33: =Q33*O33 -> 22.227325 | U33: =SUMPRODUCT(R34:R543,O34:O543)/(M33*O33) -> 1160721.1
A34: 31 | B34: =A34/Inputs!$B$6 -> 2.5833333 | C34: =Inputs!$B$3+B34 -> 67.583333 | D34: =INT(C34) -> 67 | E34: =Inputs!$B$7+1+INT((A34-1)/Inputs!$B$6) -> 2028 | F34: =Inputs!$B$16 -> 8333.3333 | G34: =Inputs!$B$12 -> 25 | H34: =IFERROR(INDEX(RP2014_Qx!$B:$B,MATCH(D34,RP2014_Qx!$A:$A,0)),"") -> 0.009679 | I34: =SUMIFS(MP2016_Long!$C:$C,MP2016_Long!$A:$A,D34,MP2016_Long!$B:$B,">=2014",MP2016_Long!$B:$B,"<"&E34) -> 0.0909 | J34: =MIN(0.999999,MAX(0,H34*EXP(I34))) -> 0.010600049 | K34: =-LN(1-J34) -> 0.010656629 | L34: =EXP(-K34/Inputs!$B$6) -> 0.99911234 | M34: =M33*L34 -> 0.97574357 | N34: =IFERROR(INDEX(MonthlyCurve!$I:$I,MATCH(A34,MonthlyCurve!$A:$A,0)),"") -> 0.037554158 | O34: =IFERROR(INDEX(MonthlyCurve!$J:$J,MATCH(A34,MonthlyCurve!$A:$A,0)),"") -> 0.90754248 | P34: =F34*M34 -> 8131.1964 | Q34: =G34*M34 -> 24.393589 | R34: =P34+Q34 -> 8155.59 | S34: =P34*O34 -> 7379.4061 | T34: =Q34*O34 -> 22.138218 | U34: =SUMPRODUCT(R35:R543,O35:O543)/(M34*O34) -> 1157034.7
A35: 32 | B35: =A35/Inputs!$B$6 -> 2.6666667 | C35: =Inputs!$B$3+B35 -> 67.666667 | D35: =INT(C35) -> 67 | E35: =Inputs!$B$7+1+INT((A35-1)/Inputs!$B$6) -> 2028 | F35: =Inputs!$B$16 -> 8333.3333 | G35: =Inputs!$B$12 -> 25 | H35: =IFERROR(INDEX(RP2014_Qx!$B:$B,MATCH(D35,RP2014_Qx!$A:$A,0)),"") -> 0.009679 | I35: =SUMIFS(MP2016_Long!$C:$C,MP2016_Long!$A:$A,D35,MP2016_Long!$B:$B,">=2014",MP2016_Long!$B:$B,"<"&E35) -> 0.0909 | J35: =MIN(0.999999,MAX(0,H35*EXP(I35))) -> 0.010600049 | K35: =-LN(1-J35) -> 0.010656629 | L35: =EXP(-K35/Inputs!$B$6) -> 0.99911234 | M35: =M34*L35 -> 0.97487744 | N35: =IFERROR(INDEX(MonthlyCurve!$I:$I,MATCH(A35,MonthlyCurve!$A:$A,0)),"") -> 0.037553907 | O35: =IFERROR(INDEX(MonthlyCurve!$J:$J,MATCH(A35,MonthlyCurve!$A:$A,0)),"") -> 0.90470736 | P35: =F35*M35 -> 8123.9787 | Q35: =G35*M35 -> 24.371936 | R35: =P35+Q35 -> 8148.3506 | S35: =P35*O35 -> 7349.8233 | T35: =Q35*O35 -> 22.04947 | U35: =SUMPRODUCT(R36:R543,O36:O543)/(M35*O35) -> 1153333.4
A36: 33 | B36: =A36/Inputs!$B$6 -> 2.75 | C36: =Inputs!$B$3+B36 -> 67.75 | D36: =INT(C36) -> 67 | E36: =Inputs!$B$7+1+INT((A36-1)/Inputs!$B$6) -> 2028 | F36: =Inputs!$B$16 -> 8333.3333 | G36: =Inputs!$B$12 -> 25 | H36: =IFERROR(INDEX(RP2014_Qx!$B:$B,MATCH(D36,RP2014_Qx!$A:$A,0)),"") -> 0.009679 | I36: =SUMIFS(MP2016_Long!$C:$C,MP2016_Long!$A:$A,D36,MP2016_Long!$B:$B,">=2014",MP2016_Long!$B:$B,"<"&E36) -> 0.0909 | J36: =MIN(0.999999,MAX(0,H36*EXP(I36))) -> 0.010600049 | K36: =-LN(1-J36) -> 0.010656629 | L36: =EXP(-K36/Inputs!$B$6) -> 0.99911234 | M36: =M35*L36 -> 0.97401209 | N36: =IFERROR(INDEX(MonthlyCurve!$I:$I,MATCH(A36,MonthlyCurve!$A:$A,0)),"") -> 0.037553655 | O36: =IFERROR(INDEX(MonthlyCurve!$J:$J,MATCH(A36,MonthlyCurve!$A:$A,0)),"") -> 0.90188113 | P36: =F36*M36 -> 8116.7674 | Q36: =G36*M36 -> 24.350302 | R36: =P36+Q36 -> 8141.1177 | S36: =P36*O36 -> 7320.3593 | T36: =Q36*O36 -> 21.961078 | U36: =SUMPRODUCT(R37:R543,O37:O543)/(M36*O36) -> 1149617.1
A37: 34 | B37: =A37/Inputs!$B$6 -> 2.8333333 | C37: =Inputs!$B$3+B37 -> 67.833333 | D37: =INT(C37) -> 67 | E37: =Inputs!$B$7+1+INT((A37-1)/Inputs!$B$6) -> 2028 | F37: =Inputs!$B$16 -> 8333.3333 | G37: =Inputs!$B$12 -> 25 | H37: =IFERROR(INDEX(RP2014_Qx!$B:$B,MATCH(D37,RP2014_Qx!$A:$A,0)),"") -> 0.009679 | I37: =SUMIFS(MP2016_Long!$C:$C,MP2016_Long!$A:$A,D37,MP2016_Long!$B:$B,">=2014",MP2016_Long!$B:$B,"<"&E37) -> 0.0909 | J37: =MIN(0.999999,MAX(0,H37*EXP(I37))) -> 0.010600049 | K37: =-LN(1-J37) -> 0.010656629 | L37: =EXP(-K37/Inputs!$B$6) -> 0.99911234 | M37: =M36*L37 -> 0.9731475 | N37: =IFERROR(INDEX(MonthlyCurve!$I:$I,MATCH(A37,MonthlyCurve!$A:$A,0)),"") -> 0.037553403 | O37: =IFERROR(INDEX(MonthlyCurve!$J:$J,MATCH(A37,MonthlyCurve!$A:$A,0)),"") -> 0.89906377 | P37: =F37*M37 -> 8109.5625 | Q37: =G37*M37 -> 24.328687 | R37: =P37+Q37 -> 8133.8912 | S37: =P37*O37 -> 7291.0138 | T37: =Q37*O37 -> 21.873041 | U37: =SUMPRODUCT(R38:R543,O38:O543)/(M37*O37) -> 1145885.9
A38: 35 | B38: =A38/Inputs!$B$6 -> 2.9166667 | C38: =Inputs!$B$3+B38 -> 67.916667 | D38: =INT(C38) -> 67 | E38: =Inputs!$B$7+1+INT((A38-1)/Inputs!$B$6) -> 2028 | F38: =Inputs!$B$16 -> 8333.3333 | G38: =Inputs!$B$12 -> 25 | H38: =IFERROR(INDEX(RP2014_Qx!$B:$B,MATCH(D38,RP2014_Qx!$A:$A,0)),"") -> 0.009679 | I38: =SUMIFS(MP2016_Long!$C:$C,MP2016_Long!$A:$A,D38,MP2016_Long!$B:$B,">=2014",MP2016_Long!$B:$B,"<"&E38) -> 0.0909 | J38: =MIN(0.999999,MAX(0,H38*EXP(I38))) -> 0.010600049 | K38: =-LN(1-J38) -> 0.010656629 | L38: =EXP(-K38/Inputs!$B$6) -> 0.99911234 | M38: =M37*L38 -> 0.97228367 | N38: =IFERROR(INDEX(MonthlyCurve!$I:$I,MATCH(A38,MonthlyCurve!$A:$A,0)),"") -> 0.037553152 | O38: =IFERROR(INDEX(MonthlyCurve!$J:$J,MATCH(A38,MonthlyCurve!$A:$A,0)),"") -> 0.89625525 | P38: =F38*M38 -> 8102.3639 | Q38: =G38*M38 -> 24.307092 | R38: =P38+Q38 -> 8126.671 | S38: =P38*O38 -> 7261.7862 | T38: =Q38*O38 -> 21.785359 | U38: =SUMPRODUCT(R39:R543,O39:O543)/(M38*O38) -> 1142139.6
A39: 36 | B39: =A39/Inputs!$B$6 -> 3 | C39: =Inputs!$B$3+B39 -> 68 | D39: =INT(C39) -> 68 | E39: =Inputs!$B$7+1+INT((A39-1)/Inputs!$B$6) -> 2028 | F39: =Inputs!$B$16 -> 8333.3333 | G39: =Inputs!$B$12 -> 25 | H39: =IFERROR(INDEX(RP2014_Qx!$B:$B,MATCH(D39,RP2014_Qx!$A:$A,0)),"") -> 0.010633 | I39: =SUMIFS(MP2016_Long!$C:$C,MP2016_Long!$A:$A,D39,MP2016_Long!$B:$B,">=2014",MP2016_Long!$B:$B,"<"&E39) -> 0.096 | J39: =MIN(0.999999,MAX(0,H39*EXP(I39))) -> 0.011704371 | K39: =-LN(1-J39) -> 0.011773406 | L39: =EXP(-K39/Inputs!$B$6) -> 0.99901936 | M39: =M38*L39 -> 0.97133022 | N39: =IFERROR(INDEX(MonthlyCurve!$I:$I,MATCH(A39,MonthlyCurve!$A:$A,0)),"") -> 0.0375529 | O39: =IFERROR(INDEX(MonthlyCurve!$J:$J,MATCH(A39,MonthlyCurve!$A:$A,0)),"") -> 0.89345554 | P39: =F39*M39 -> 8094.4185 | Q39: =G39*M39 -> 24.283255 | R39: =P39+Q39 -> 8118.7017 | S39: =P39*O39 -> 7232.0031 | T39: =Q39*O39 -> 21.696009 | U39: =SUMPRODUCT(R40:R543,O40:O543)/(M39*O39) -> 1138484.8
A40: 37 | B40: =A40/Inputs!$B$6 -> 3.0833333 | C40: =Inputs!$B$3+B40 -> 68.083333 | D40: =INT(C40) -> 68 | E40: =Inputs!$B$7+1+INT((A40-1)/Inputs!$B$6) -> 2029 | F40: =Inputs!$B$16 -> 8333.3333 | G40: =Inputs!$B$12 -> 25 | H40: =IFERROR(INDEX(RP2014_Qx!$B:$B,MATCH(D40,RP2014_Qx!$A:$A,0)),"") -> 0.010633 | I40: =SUMIFS(MP2016_Long!$C:$C,MP2016_Long!$A:$A,D40,MP2016_Long!$B:$B,">=2014",MP2016_Long!$B:$B,"<"&E40) -> 0.106 | J40: =MIN(0.999999,MAX(0,H40*EXP(I40))) -> 0.011822002 | K40: =-LN(1-J40) -> 0.011892438 | L40: =EXP(-K40/Inputs!$B$6) -> 0.99900945 | M40: =M39*L40 -> 0.97036807 | N40: =IFERROR(INDEX(MonthlyCurve!$I:$I,MATCH(A40,MonthlyCurve!$A:$A,0)),"") -> 0.037591702 | O40: =IFERROR(INDEX(MonthlyCurve!$J:$J,MATCH(A40,MonthlyCurve!$A:$A,0)),"") -> 0.89055738 | P40: =F40*M40 -> 8086.4006 | Q40: =G40*M40 -> 24.259202 | R40: =P40+Q40 -> 8110.6598 | S40: =P40*O40 -> 7201.4037 | T40: =Q40*O40 -> 21.604211 | U40: =SUMPRODUCT(R41:R543,O41:O543)/(M40*O40) -> 1134964
...

Sheet Dashboard
A1: SPIA Policy Projection Dashboard
A3: Policy Inputs | D3: Expense Assumptions
A4: Issue Age | B4: =Inputs!B3 -> 65 | D4: Policy Expense ($) | E4: =Inputs!B10 -> 250
A5: Sex | B5: =Inputs!B4 -> male | D5: Premium Expense Rate | E5: =Inputs!B11 -> 0.01
A6: Annual Benefit | B6: =Inputs!B5 -> 100000 | D6: Monthly Expense ($) | E6: =Inputs!B12 -> 25
A7: Valuation Year (12/31) | B7: =Inputs!B7 -> 2025
A8: Horizon Age | B8: =Inputs!B8 -> 110
A9: Spread | B9: =Inputs!B9 -> 0
A11: Pricing & Reserve Summary
A12: Single Premium | B12: =Projection!X8 -> 1281342.4
A13: PV Benefits | B13: =Projection!X4 -> 1264485.5
A14: PV Monthly Expenses | B14: =Projection!X5 -> 3793.4566
A15: PV Monthly Total | B15: =Projection!X7 -> 1268279
A16: Annuity Factor | B16: =Projection!X6 -> 151.73826
A17: Economic Reserve at t=0 | B17: =Projection!U2 -> 1268279
A54: Checkpoint Metrics (Nearest Monthly Projection Point)
A55: Target Age | B55: Projection Row | C55: Survival | D55: Exp Benefit ($) | E55: Exp Expense ($) | F55: Reserve ($)
A56: 65 | B56: =IFERROR(MATCH(A56,Projection!$C$4:$C$543,0)+3,IF(A56<INDEX(Projection!$C$4:$C$543,1),4,MATCH(A56,Projection!$C$4:$C$543,1)+3)) -> 4 | C56: =INDEX(Projection!$M:$M,B56) -> 0.99928225 | D56: =INDEX(Projection!$P:$P,B56) -> 8327.3521 | E56: =INDEX(Projection!$Q:$Q,B56) -> 24.982056 | F56: =INDEX(Projection!$U:$U,B56) -> 1264777.6
A57: 70 | B57: =IFERROR(MATCH(A57,Projection!$C$4:$C$543,0)+3,IF(A57<INDEX(Projection!$C$4:$C$543,1),4,MATCH(A57,Projection!$C$4:$C$543,1)+3)) -> 63 | C57: =INDEX(Projection!$M:$M,B57) -> 0.94695511 | D57: =INDEX(Projection!$P:$P,B57) -> 7891.2926 | E57: =INDEX(Projection!$Q:$Q,B57) -> 23.673878 | F57: =INDEX(Projection!$U:$U,B57) -> 1053573.6
A58: 75 | B58: =IFERROR(MATCH(A58,Projection!$C$4:$C$543,0)+3,IF(A58<INDEX(Projection!$C$4:$C$543,1),4,MATCH(A58,Projection!$C$4:$C$543,1)+3)) -> 123 | C58: =INDEX(Projection!$M:$M,B58) -> 0.86181019 | D58: =INDEX(Projection!$P:$P,B58) -> 7181.7516 | E58: =INDEX(Projection!$Q:$Q,B58) -> 21.545255 | F58: =INDEX(Projection!$U:$U,B58) -> 866218.58
A59: 80 | B59: =IFERROR(MATCH(A59,Projection!$C$4:$C$543,0)+3,IF(A59<INDEX(Projection!$C$4:$C$543,1),4,MATCH(A59,Projection!$C$4:$C$543,1)+3)) -> 183 | C59: =INDEX(Projection!$M:$M,B59) -> 0.73484967 | D59: =INDEX(Projection!$P:$P,B59) -> 6123.7473 | E59: =INDEX(Projection!$Q:$Q,B59) -> 18.371242 | F59: =INDEX(Projection!$U:$U,B59) -> 695260.79
A60: 85 | B60: =IFERROR(MATCH(A60,Projection!$C$4:$C$543,0)+3,IF(A60<INDEX(Projection!$C$4:$C$543,1),4,MATCH(A60,Projection!$C$4:$C$543,1)+3)) -> 243 | C60: =INDEX(Projection!$M:$M,B60) -> 0.55815242 | D60: =INDEX(Projection!$P:$P,B60) -> 4651.2701 | E60: =INDEX(Projection!$Q:$Q,B60) -> 13.95381 | F60: =INDEX(Projection!$U:$U,B60) -> 559243.09
A61: 90 | B61: =IFERROR(MATCH(A61,Projection!$C$4:$C$543,0)+3,IF(A61<INDEX(Projection!$C$4:$C$543,1),4,MATCH(A61,Projection!$C$4:$C$543,1)+3)) -> 303 | C61: =INDEX(Projection!$M:$M,B61) -> 0.34251823 | D61: =INDEX(Projection!$P:$P,B61) -> 2854.3186 | E61: =INDEX(Projection!$Q:$Q,B61) -> 8.5629558 | F61: =INDEX(Projection!$U:$U,B61) -> 408366.5
A62: 100 | B62: =IFERROR(MATCH(A62,Projection!$C$4:$C$543,0)+3,IF(A62<INDEX(Projection!$C$4:$C$543,1),4,MATCH(A62,Projection!$C$4:$C$543,1)+3)) -> 423 | C62: =INDEX(Projection!$M:$M,B62) -> 0.034570343 | D62: =INDEX(Projection!$P:$P,B62) -> 288.08619 | E62: =INDEX(Projection!$Q:$Q,B62) -> 0.86425857 | F62: =INDEX(Projection!$U:$U,B62) -> 213792.44
A63: 110 | B63: =IFERROR(MATCH(A63,Projection!$C$4:$C$543,0)+3,IF(A63<INDEX(Projection!$C$4:$C$543,1),4,MATCH(A63,Projection!$C$4:$C$543,1)+3)) -> 543 | C63: =INDEX(Projection!$M:$M,B63) -> 0.00023178081 | D63: =INDEX(Projection!$P:$P,B63) -> 1.9315068 | E63: =INDEX(Projection!$Q:$Q,B63) -> 0.0057945203 | F63: =INDEX(Projection!$U:$U,B63) -> 0

Sheet Python_Runbook
A1: Python Runbook / Repro Steps
A3: Purpose | B3: This tab documents how to run and regenerate the SPIA Python model artifacts.
A4: Working folder | B4: annuity_model
A5: Python version | B5: Use Python 3.11+ recommended.
A6: Dependencies | B6: numpy, pandas, openpyxl, matplotlib
A8: Core commands | B8: From the annuity_model folder run:
A9: 1 | B9: python spia_projection.py
A10: 2 | B10: python illustrate_spia_projection.py
A11: 3 | B11: python build_spia_excel_workbook.py
A13: Inputs used by Python | B13: treasury_zero_rate_curve_latest.csv
B14: rp2014_mort_tab_rates_exposure.xlsx
B15: mp2016_rates.xlsx
B16: expenses_assumptions_us_placeholders.csv
A18: Outputs generated by Python | B18: spia_projection_model.xlsx
B19: illustrations/*.png
B20: rp2014_male_healthy_annuitant_qx_2014.csv
B21: mp2016_male_improvement_rates.csv
A23: Python in Excel note | B23: If your Excel has Python-in-Excel, you can use =PY() cells.
A24: Example | B24: {=_xlfn._xlws.PY(0,1)} -> import pandas as pd; pd.read_csv('treasury_zero_rate_curve_latest.csv').head()
A25: Example | B25: {=_xlfn._xlws.PY(1,1)} -> from spia_projection import _example_usage; _example_usage()
A27: Caveat | B27: Python-in-Excel runs in Microsoft sandbox; local file access may be restricted.
A28: Recommendation | B28: Use terminal commands above for production reproducibility.
A35: spia_projection.py (excerpt)
A36: """ Single Premium Immediate Annuity (SPIA) projection scaffolding. Contract assumptions (set from the conversation): - Single life - Level monthly payments, benefit is provided as an annual amount (default: 100_000) - Payment timing: end of period - Payments stop at death (i.e., pay at time t_k iff alive at that payment date) Pricing (single premium): Premium = sum_{k=1..N} (B_annual/12) * P(alive at t_k) * DF(t_k) Interest: - Uses continuous-compounding "zero rates" z(t). Discount factors: DF(t) = exp(-(z(t) + spread) * t) - Risk-free by default: spread = 0. US industry mortality (table selection, data must be supplied): - RP-2014 Healthy Annuitant Male base table - MP-2016 mortality improvement scale Important: - RP-2014 and MP-2016 are proprietary to SOA. - This code does NOT embed the table rates. - Provide annual one-year death probabilities q_x (or equivalent) in a CSV. """ from __future__ import annotations from dataclasses import dataclass from typing import Literal, Optional, Sequence, Tuple import math import numpy as np import pandas as pd Compounding = Literal["continuous"] DEFAULT_ZERO_CURVE_CSV = "treasury_zero_rate_curve_latest.csv" DEFAULT_PAR_CURVE_CSV = "treasury_par_yield_curve_latest.csv" DEFAULT_MORTALITY_QX_CSV = "rp2014_male_annuitant_qx.csv" DEFAULT_RP2014_XLSX = "rp2014_mort_tab_rates_exposure.xlsx" DEFAULT_MP2016_XLSX = "mp2016_rates.xlsx" DEFAULT_RP2014_MALE_HEALTHY_QX_CSV = "rp2014_male_healthy_annuitant_qx_2014.csv" DEFAULT_MP2016_MALE_IMPROVEMENT_CSV = "mp2016_male_improvement_rates.csv" DEFAULT_EXPENSES_CSV = "expenses_assumptions_us_placeholders.csv" @dataclass(frozen=True) class YieldCurve: """ Continuous-compounding zero curve. Attributes ---------- maturities_years: Array of curve node maturities in years (e.g., [0.5, 1.0, 1.5, ...]). zero_rates: Corresponding continuously-compounded spot/zero rates z(t). """ maturities_years: np.ndarray zero_rates: np.ndarray @staticmethod def from_flat_rate(flat_zero_rate: float) -> "YieldCurve": mats = np.array([0.0, 1.0], dtype=float) zeros = np.array([flat_zero_rate, flat_zero_rate], dtype=float) return YieldCurve(mats, zeros) @staticmethod def load_zero_curve_csv( path: str, *, maturity_col: str = "maturity_years", rate_col: str = "zero_rate", ) -> "YieldCurve": df = pd.read_csv(path) mats = df[maturity_col].to_numpy(dtype=float) zeros = df[rate_col].to_numpy(dtype=float) order = np.argsort(mats) return YieldCurve(mats[order], zeros[order]) @staticmethod def load_par_yield_csv_and_bootstrap( path: str, *, maturity_col: str = "maturity_years", par_rate_col: str = "par_yield", coupon_freq: int = 2, interpolation: Literal["linear"] = "linear", ) -> "YieldCurve": """ Bootstrap discount factors from a par-yield curve. Inputs note: - Treasury par yields are commonly quoted with semiannual coupons. - To bootstrap discount factors on the coupon grid, this function will linearly interpolate the par yields onto each coupon date. - This is sufficient for a scaffold; later you can replace with a more faithful bootstrapping approach as needed. """ df = pd.read_csv(path) maturities = df[maturity_col].to_numpy(dtype=float) par_yields = df[par_rate_col].to_numpy(dtype=float) order = np.argsort(maturities) maturities = maturities[order] par_yields = par_yields[order] zero_mats, zero_rates = bootstrap_zero_rates_from_par_yields( par_maturities_years=maturities, par_yields=par_yields, coupon_freq=coupon_freq, ) return YieldCurve(zero_mats, zero_rates) def discount_factors( self, times_years: np.ndarray, *, spread: float = 0.0, compounding: Compounding = "continuous", ) -> np.ndarray: """ Convert the stored zero curve into discount factors at arbitrary times. Uses log-linear interpolation on discount factors (stable). """ if compounding != "continuous": raise ValueError("Only continuous compounding is implemented.") t = np.asarray(times_years, dtype=float) if t.ndim != 1: raise ValueError("times_years must be a 1D array.") # Ensure increasing curve times. mats = np.asarray(self.maturities_years, dtype=float)
A95: illustrate_spia_projection.py (excerpt)
